Workbook

Sheet Val Size
D1: Working Hours | E1: Per Shift (seconds) | F1: Per Day Seconds | H1: Summary Total Downtime | K1: Summary For OEE (%) | M1: OEE (%)
B2: Assumption | C2: Hours / Shift | D2: ='Client Data'!C107 -> 8 | E2: =D2*60*60 -> 28800 | F2: =E2*D3 -> 86400 | H2: SDT (secs) | I2: ='Micro Data Tabulation'!BC92 -> 1309320 | K2: Overall Equipment Effectiveness | L2: =L3*L4*L5 -> 0.78739837 | M2: =L2*100 -> 78.739837
C3: Shift / Day | D3: ='Client Data'!F106 -> 3 | F3: =F2*C8 -> 31449600 | G3: Closed Loop Check | H3: USDT (Hour) | I3: ='Micro Data Tabulation'!BC94 -> 167.1 | K3: Availability | L3: =L6/L7 -> 0.98004133 | M3: =L3*100 -> 98.004133
B4: Operation Day / Week | C4: Total Production Planned Time (Seconds) | F4: =F3-I2 -> 30140280 | G4: =IF(F4='Micro Data Tabulation'!BC90,TRUE,FALSE) -> TRUE | H4: USDT (Seconds) | I4: =I3*60*60 -> 601560 | K4: Performance | L4: =F16*E9/L6 -> 0.80379583 | M4: =L4*100 -> 80.379583
B5: ='Client Data'!F107 -> 7 | C5: Total Operation Time (seconds) | F5: =F4-I4 -> 29538720 | G5: =IF(F5='Micro Data Tabulation'!BC96,TRUE,FALSE) -> TRUE | H5: Utilization Target | I5: ='Client Data'!C106 -> 0.9 | K5: Quality | L5: =(1-E14) -> 0.99954966 | M5: =L5*100 -> 99.954966
B6: =C8/B5 -> 52 | K6: Operating Time | L6: =L7-I4 -> 29538720
C7: Validation Range (Day) | D7: DT | E7: Operation Time(sec) | F7: Cycle Time/ Unit(Sec) | G7: Manning Ratio | K7: Planned Production Time | L7: =F4 -> 30140280
B8: Analysis Time Period | C8: ='Client Data'!J106 -> 364 | D8: =I2+I4 -> 1910880 | E8: =F5 -> 29538720 | F8: =E8/E9 -> 12.645 | G8: ='Client Data'!S106 -> 2
B9: Total Volume (units) | C9: ='Micro Data Tabulation'!BC57 -> 2336000 | D9: 0 | E9: =C9 -> 2336000
B10: Average KPI Summary
B11: Category | C11: Metric Description | D11: Unit | E11: Current Value | F11: Target Value | G11: Gap | H11: Notes | K11: Rework Loss / Unit | L11: =SUM(L17,L16,L15,L14) -> 0
B12: Unscheduled Downtime | C12: Machine Failure | D12: Hours | E12: ='Micro Data Tabulation'!BC94 -> 167.1 | F12: ='Client Data'!J107 -> 0 | G12: =F12-E12 -> -167.1 | H12: =IF(G12<0,1,0) -> 1 | K12: Rework Time/unit (sec) | L12: ='Client Data'!S107 -> 0
B13: Unscheduled Downtime | C13: Machine Assist | D13: Hours | E13: 0 | F13: ='Client Data'!J107 -> 0 | G13: =F13-E13 -> 0 | H13: =IF(G13<0,1,0) -> 0 | K13: Labor Rate/sec (rm/sec) | L13: =L35/60/60 -> 0.0066666667
B14: Quality Loss (Yield Loss) | C14: Defect Rate (-Yield) | D14: % Percent | E14: =1-'Micro Data Tabulation'!BC64 -> 0.00045034247 | F14: =1-'Client Data'!M106 -> 0.00024645548 | G14: =F14-E14 -> -0.00020388699 | H14: =IF(G14<0,1,0) -> 1 | K14: Extra Labor Cost (RM) | L14: =L12*L13 -> 0
B15: Quality Loss (Rework Loss) | C15: Rework Rate | D15: % Percent | E15: ='Micro Data Tabulation'!BC75/'Micro Data Tabulation'!BC57 -> 0.0021592466 | F15: ='Client Data'!M107 -> 0.00041862158 | G15: =F15-E15 -> -0.001740625 | H15: =IF(G15<0,1,0) -> 1 | K15: Extra Material Cost / unit | L15: ='Client Data'!W106 -> 0
B16: Speed Loss (ACT-TCT) | C16: Actual Vs POR CT | D16: Seconds | E16: =F8 -> 12.645 | F16: ='Client Data'!P106 -> 10.163998 | G16: =F16-E16 -> -2.4810017 | H16: =IF(G16<0,1,0) -> 1 | K16: Extra Utility Cost / unit | L16: ='Client Data'!W107 -> 0
B17: Labor Loss | C17: Extra Manpower | D17: Headcount | E17: =D2*D3*C8*G8 -> 17472 | F17: =C9*F16*G8/60/60 -> 13190.611 | G17: =F17-E17 -> -4281.3889 | H17: =IF(G17<0,1,0) -> 1 | K17: Opportunity Cost / Unit | L17: =L20*L12/L19 -> 0
B18: Utility Waste | C18: Excess Consumption | D18: RM | E18: =D48 -> 73000 | F18: =E48 -> 53728 | G18: =F18-E18 -> -19272 | H18: =IF(G18<0,1,0) -> 1 | K18: Speed Loss (CT) - Overall | L18: =G16*(-1) -> 2.4810017
B19: Customer Return (unit) | C19: Mis-Processing | D19: Units | E19: ='Client Data'!P107 -> 12 | F19: 0 | G19: =F19-E19 -> -12 | H19: =IF(G19<0,1,0) -> 1 | K19: Standard Cycle Time | L19: =F16 -> 10.163998
B20: Material Waste | C20: Over-Consumption | D20: RM | E20: =D64 -> 122000 | F20: =E64 -> 85264 | G20: =F20-E20 -> -36736 | H20: =IF(G20<0,1,0) -> 1 | K20: Contribution Margin / Unit | L20: =L21-L22 -> -16.089753
B21: Tooling / Consumables | C21: Premature Wear / Tear / Etc | D21: RM | E21: =D78 -> 173000 | F21: =E78 -> 149504 | G21: =F21-E21 -> -23496 | H21: =IF(G21<0,1,0) -> 1 | K21: Selling Price / unit | L21: ='Client Data'!Z106 -> 0
K22: Variable Cost / Unit (avg) | L22: =L26 -> 16.089753
K26: Defect Loss Per Unit (Scrap) | L26: =SUM(L27:L29) -> 16.089753
K27: Material Cost per unit | L27: ='Client Data'!Z107 -> 8
B28: Category | C28: Gap Value (Per Val Size) | D28: Cost / Unit | E28: Val Size VaS | F28: Annual VaS | G28: 5 Years VaS | H28: LoGICAL Test | K28: Direct Labor Cost Per unit | L28: =L37/C9*L32 -> 0.089753425
B29: USDT - Machine Failure | C29: =G12*(-1) -> 167.1 | D29: ='Micro Data Tabulation'!W4 -> 2573.6832 | E29: =C29*D29 -> 430062.47 | F29: =E29/B6*52 -> 430062.47 | G29: =F29*5 -> 2150312.3 | H29: =AND(E29,'Micro Data Tabulation'!C180) -> TRUE | K29: Utility Cost Per Unit | L29: ='Client Data'!AC106 -> 8
B30: USDT - Machine Assist | C30: =G13*(-1) -> 0 | D30: =D29 -> 2573.6832 | E30: =C30*D30 -> 0 | F30: =E30/B6*52 -> 0 | G30: =F30*5 -> 0
B31: Quality Loss - Defect | C31: =C9*G14*-1 -> 476.28 | D31: =SUM('Micro Data Tabulation'!BC445:BC452)/('Val Size'!G14*(-1)*'Val Size'!C9) -> 16.051252 | E31: =C31*D31 -> 7644.8905 | F31: =E31/(B6)*52 -> 7644.8905 | G31: =F31*5 -> 38224.453 | H31: =AND(E31,SUM('Micro Data Tabulation'!BC445:BC452)) -> TRUE | K31: Cost Per Hour Downtime | L31: =SUM(L33,L34,L35) -> -5644.8511
B32: Quality Loss - Rework | C32: =C9*G15*(-1) -> 4066.1 | D32: =SUM('Micro Data Tabulation'!BC714:BC721)/(-1*SUM('Micro Data Tabulation'!BC763:BC782)*'Val Size'!G15) -> 14.745328 | E32: =C32*D32 -> 59955.976 | F32: =E32/(B6)*52 -> 59955.976 | G32: =F32*5 -> 299779.88 | H32: =AND(E32,SUM('Micro Data Tabulation'!BC714:BC721)) -> TRUE | K32: Labor Cost Per Hour / Pax | L32: ='Client Data'!AC107 -> 12
B33: Speed Loss | C33: =G16*-1*E9 -> 5795620 | D33: ='Micro Data Tabulation'!C318/60/60 -> 0.75103448 | E33: =C33*D33 -> 4352710.5 | F33: =E33/B6*52 -> 4352710.5 | G33: =F33*5 -> 21763552 | H33: =AND(E33,'Micro Data Tabulation'!BD848) -> TRUE | K33: Overhead Cost Per Hour | L33: ='Client Data'!AF106 -> 30
B34: Labor Loss | C34: =L38 -> 4281.3889 | D34: =L32 -> 12 | E34: =C34*D34 -> 51376.667 | F34: =E34/B6*52 -> 51376.667 | G34: =F34*5 -> 256883.33 | H34: =AND(E34,'Micro Data Tabulation'!BB759) -> TRUE | K34: Opportunity Cost Per Hour | L34: =L20*(60*60)/F16 -> -5698.8511
B35: Utility Waste | C35: =G18*-1 -> 19272 | D35: =1 -> 1 | E35: =C35*D35 -> 19272 | F35: =E35/B6*52 -> 19272 | G35: =F35*5 -> 96360 | K35: Total Labor Cost With Labor Count)/Hour | L35: =L32*G8 -> 24
B36: Customer Return | C36: =G19*-1 -> 12 | D36: =L26 -> 16.089753 | E36: =C36*D36 -> 193.07704 | F36: =E36/B6*52 -> 193.07704 | G36: =F36*5 -> 965.38521 | K36: Standard Labor Hours (SLH) | L36: =G8*F16*C9/60/60 -> 13190.611
B37: Material Waste | C37: =G20*-1 -> 36736 | D37: =1 -> 1 | E37: =C37*D37 -> 36736 | F37: =E37/B6*52 -> 36736 | G37: =F37*5 -> 183680 | K37: Actual Labor hours (ALH) | L37: =D2*D3*C8*G8 -> 17472
B38: Tooling / Consulables Waste | C38: =G21*-1 -> 23496 | D38: =1 -> 1 | E38: =C38*D38 -> 23496 | F38: =E38/B6*52 -> 23496 | G38: =F38*5 -> 117480 | K38: Labor Loss (Hours) | L38: =L37-L36 -> 4281.3889
D39: TOTAL | E39: =SUM(E29:E38) -> 4981447.5
B42: Energy / Utility Waste | C42: Multiplier Constant, K | D42: Actual Utilization (RM) | E42: Target Utilization (RM) | F42: Waste (RM)
B43: Electricity | C43: 0.01 | D43: 15000 | E43: =C43*C9 -> 23360 | F43: =D43-E43 -> -8360
B44: Gas | C44: 0.005 | D44: 36000 | E44: =C44*C9 -> 11680 | F44: =D44-E44 -> 24320
B45: Water | C45: 0.008 | D45: 22000 | E45: =C45*C9 -> 18688 | F45: =D45-E45 -> 3312
...

Sheet Client Data
A1: Product Count
A2: 8 | B2: Product Name | C2: Standard CT (Seconds) | D2: 1 | E2: =D2+1 -> 2 | F2: =E2+1 -> 3 | G2: =F2+1 -> 4 | H2: =G2+1 -> 5 | I2: =H2+1 -> 6 | J2: =I2+1 -> 7 | K2: =J2+1 -> 8 | L2: =K2+1 -> 9 | ... BC2: =BB2+1 -> 52 | BD2: ='Micro Data Tabulation'!BC56 -> TOTAL | BE2: Total | BF2: Rework Extra Material Cost / Unit (RM) | BG2: Rework: Extra Utility Cost (RM) | BH2: Product Price / Unit (RM) | BI2: Material Cost / Unit (RM) | BJ2: Utility Cost / Unit (RM) | BK2: Yeild Target (%) | BL2: Customer Return
A3: 1 | B3: Product A | C3: 9 | D3: 9000 | E3: 0 | F3: 5000 | G3: 0 | H3: 9000 | I3: 0 | J3: 0 | K3: 0 | L3: 9000 | M3: 0 | N3: 0 | O3: 0 | P3: 9000 | Q3: 3000 | R3: 0 | S3: 0 | T3: 9000 | U3: 0 | V3: 0 | W3: 3000 | X3: 9000 | Y3: 0 | Z3: 0 | AA3: 0 | AB3: 9000 | AC3: 0 | AD3: 6000 | AE3: 0 | AF3: 9000 | AG3: 0 | AH3: 0 | AI3: 3000 | AJ3: 9000 | AK3: 0 | AL3: 0 | AM3: 0 | AN3: 9000 | AO3: 3000 | AP3: 0 | AQ3: 0 | AR3: 9000 | AS3: 0 | AT3: 5000 | AU3: 0 | AV3: 9000 | AW3: 5000 | AX3: 0 | AY3: 0 | AZ3: 9000 | BA3: 0 | BB3: 0 | BC3: 0 | BD3: =SUM(D3:BC3) -> 150000 | BE3: =C3*BD3 -> 1350000 | BF3: 0.24 | BG3: 0.26 | BH3: 26 | BI3: 7 | BJ3: 8.5 | BK3: 0.9997 | BL3: 1
A4: 2 | B4: Product B | C4: 9.8 | D4: 8000 | E4: 9000 | F4: 0 | G4: 6000 | H4: 8000 | I4: 9000 | J4: 0 | K4: 3000 | L4: 8000 | M4: 9000 | N4: 0 | O4: 0 | P4: 8000 | Q4: 9000 | R4: 0 | S4: 0 | T4: 8000 | U4: 9000 | V4: 0 | W4: 0 | X4: 8000 | Y4: 9000 | Z4: 0 | AA4: 0 | AB4: 8000 | AC4: 9000 | AD4: 0 | AE4: 0 | AF4: 8000 | AG4: 9000 | AH4: 0 | AI4: 0 | AJ4: 8000 | AK4: 9000 | AL4: 0 | AM4: 0 | AN4: 8000 | AO4: 9000 | AP4: 0 | AQ4: 0 | AR4: 8000 | AS4: 9000 | AT4: 0 | AU4: 5000 | AV4: 8000 | AW4: 9000 | AX4: 0 | AY4: 3000 | AZ4: 8000 | BA4: 3000 | BB4: 0 | BC4: 0 | BD4: =SUM(D4:BC4) -> 232000 | BE4: =C4*BD4 -> 2273600 | BF4: 0.23 | BG4: 0.23 | BH4: 25 | BI4: 8 | BJ4: 8.9 | BK4: 0.99971 | BL4: 2
A5: 3 | B5: Product C | C5: 9.6 | D5: 10000 | E5: 8000 | F5: 9000 | G5: 0 | H5: 10000 | I5: 8000 | J5: 9000 | K5: 0 | L5: 10000 | M5: 8000 | N5: 9000 | O5: 0 | P5: 10000 | Q5: 8000 | R5: 9000 | S5: 0 | T5: 10000 | U5: 8000 | V5: 9000 | W5: 0 | X5: 10000 | Y5: 8000 | Z5: 9000 | AA5: 0 | AB5: 10000 | AC5: 8000 | AD5: 9000 | AE5: 0 | AF5: 10000 | AG5: 8000 | AH5: 9000 | AI5: 0 | AJ5: 10000 | AK5: 8000 | AL5: 9000 | AM5: 0 | AN5: 10000 | AO5: 8000 | AP5: 9000 | AQ5: 0 | AR5: 10000 | AS5: 8000 | AT5: 9000 | AU5: 0 | AV5: 10000 | AW5: 8000 | AX5: 9000 | AY5: 0 | AZ5: 10000 | BA5: 8000 | BB5: 9000 | BC5: 0 | BD5: =SUM(D5:BC5) -> 351000 | BE5: =C5*BD5 -> 3369600 | BF5: 0.22 | BG5: 0.25 | BH5: 24 | BI5: 6 | BJ5: 9 | BK5: 0.99975 | BL5: 2
A6: 4 | B6: Product D | C6: 11 | D6: 13000 | E6: 10000 | F6: 8000 | G6: 9000 | H6: 9000 | I6: 10000 | J6: 8000 | K6: 9000 | L6: 13000 | M6: 10000 | N6: 8000 | O6: 9000 | P6: 13000 | Q6: 10000 | R6: 8000 | S6: 9000 | T6: 9000 | U6: 8000 | V6: 8000 | W6: 9000 | X6: 13000 | Y6: 10000 | Z6: 8000 | AA6: 7000 | AB6: 13000 | AC6: 10000 | AD6: 8000 | AE6: 9000 | AF6: 9000 | AG6: 10000 | AH6: 8000 | AI6: 9000 | AJ6: 13000 | AK6: 10000 | AL6: 8000 | AM6: 7000 | AN6: 13000 | AO6: 10000 | AP6: 8000 | AQ6: 9000 | AR6: 9000 | AS6: 10000 | AT6: 8000 | AU6: 9000 | AV6: 13000 | AW6: 10000 | AX6: 8000 | AY6: 9000 | AZ6: 13000 | BA6: 10000 | BB6: 8000 | BC6: 7000 | BD6: =SUM(D6:BC6) -> 496000 | BE6: =C6*BD6 -> 5456000 | BF6: 0.21 | BG6: 0.22 | BH6: 21 | BI6: 8.5 | BJ6: 8 | BK6: 0.99979 | BL6: 1
A7: 5 | B7: Product E | C7: 10.8 | D7: 5000 | E7: 13000 | F7: 10000 | G7: 8000 | H7: 5000 | I7: 11000 | J7: 10000 | K7: 8000 | L7: 5000 | M7: 7000 | N7: 6000 | O7: 8000 | P7: 5000 | Q7: 13000 | R7: 10000 | S7: 8000 | T7: 5000 | U7: 13000 | V7: 10000 | W7: 8000 | X7: 5000 | Y7: 7000 | Z7: 10000 | AA7: 8000 | AB7: 5000 | AC7: 13000 | AD7: 10000 | AE7: 8000 | AF7: 5000 | AG7: 11000 | AH7: 10000 | AI7: 8000 | AJ7: 5000 | AK7: 7000 | AL7: 10000 | AM7: 8000 | AN7: 5000 | AO7: 13000 | AP7: 10000 | AQ7: 8000 | AR7: 5000 | AS7: 11000 | AT7: 10000 | AU7: 8000 | AV7: 5000 | AW7: 13000 | AX7: 10000 | AY7: 8000 | AZ7: 5000 | BA7: 13000 | BB7: 10000 | BC7: 8000 | BD7: =SUM(D7:BC7) -> 440000 | BE7: =C7*BD7 -> 4752000 | BF7: 0.23 | BG7: 0.24 | BH7: 23 | BI7: 8 | BJ7: 7.8 | BK7: 0.99976 | BL7: 2
A8: 6 | B8: Product F | C8: 10.5 | D8: 0 | E8: 5000 | F8: 13000 | G8: 0 | H8: 0 | I8: 5000 | J8: 13000 | K8: 10000 | L8: 6000 | M8: 5000 | N8: 13000 | O8: 10000 | P8: 0 | Q8: 5000 | R8: 13000 | S8: 10000 | T8: 0 | U8: 5000 | V8: 13000 | W8: 10000 | X8: 0 | Y8: 5000 | Z8: 9000 | AA8: 10000 | AB8: 0 | AC8: 5000 | AD8: 13000 | AE8: 4000 | AF8: 0 | AG8: 5000 | AH8: 13000 | AI8: 10000 | AJ8: 0 | AK8: 5000 | AL8: 9000 | AM8: 10000 | AN8: 0 | AO8: 5000 | AP8: 13000 | AQ8: 4000 | AR8: 0 | AS8: 5000 | AT8: 13000 | AU8: 10000 | AV8: 5000 | AW8: 5000 | AX8: 13000 | AY8: 10000 | AZ8: 6000 | BA8: 5000 | BB8: 9000 | BC8: 10000 | BD8: =SUM(D8:BC8) -> 347000 | BE8: =C8*BD8 -> 3643500 | BF8: 0.24 | BG8: 0.25 | BH8: 22 | BI8: 9 | BJ8: 7.9 | BK8: 0.99973 | BL8: 1
A9: 7 | B9: Product G | C9: 9 | D9: 0 | E9: 3000 | F9: 6000 | G9: 11000 | H9: 0 | I9: 0 | J9: 5000 | K9: 13000 | L9: 0 | M9: 0 | N9: 5000 | O9: 11000 | P9: 0 | Q9: 0 | R9: 5000 | S9: 7000 | T9: 0 | U9: 0 | V9: 5000 | W9: 13000 | X9: 0 | Y9: 0 | Z9: 5000 | AA9: 13000 | AB9: 0 | AC9: 0 | AD9: 5000 | AE9: 13000 | AF9: 0 | AG9: 0 | AH9: 5000 | AI9: 13000 | AJ9: 0 | AK9: 0 | AL9: 5000 | AM9: 13000 | AN9: 0 | AO9: 0 | AP9: 5000 | AQ9: 13000 | AR9: 0 | AS9: 0 | AT9: 5000 | AU9: 13000 | AV9: 0 | AW9: 0 | AX9: 5000 | AY9: 13000 | AZ9: 0 | BA9: 0 | BB9: 5000 | BC9: 13000 | BD9: =SUM(D9:BC9) -> 228000 | BE9: =C9*BD9 -> 2052000 | BF9: 0.22 | BG9: 0.25 | BH9: 24 | BI9: 6.9 | BJ9: 8 | BK9: 0.99978 | BL9: 2
A10: 8 | B10: Product H | C10: 9.2 | D10: 0 | E10: 0 | F10: 0 | G10: 5000 | H10: 0 | I10: 0 | J10: 0 | K10: 5000 | L10: 0 | M10: 0 | N10: 0 | O10: 5000 | P10: 0 | Q10: 0 | R10: 6000 | S10: 5000 | T10: 0 | U10: 0 | V10: 0 | W10: 5000 | X10: 6000 | Y10: 0 | Z10: 0 | AA10: 5000 | AB10: 0 | AC10: 3000 | AD10: 0 | AE10: 5000 | AF10: 0 | AG10: 0 | AH10: 0 | AI10: 5000 | AJ10: 6000 | AK10: 0 | AL10: 0 | AM10: 5000 | AN10: 0 | AO10: 0 | AP10: 6000 | AQ10: 5000 | AR10: 0 | AS10: 0 | AT10: 0 | AU10: 5000 | AV10: 0 | AW10: 0 | AX10: 0 | AY10: 5000 | AZ10: 0 | BA10: 0 | BB10: 0 | BC10: 5000 | BD10: =SUM(D10:BC10) -> 92000 | BE10: =C10*BD10 -> 846400 | BF10: 0.25 | BG10: 0.22 | BH10: 26 | BI10: 7.8 | BJ10: 7.5 | BK10: 0.99976 | BL10: 1
A11: 9 | BD11: =SUM(D11:BC11) -> 0 | BE11: =C11*BD11 -> 0
A12: 10 | BD12: =SUM(D12:BC12) -> 0 | BE12: =C12*BD12 -> 0
A13: 11 | BD13: =SUM(D13:BC13) -> 0 | BE13: =C13*BD13 -> 0
A14: 12 | BD14: =SUM(D14:BC14) -> 0 | BE14: =C14*BD14 -> 0
A15: 13 | BD15: =SUM(D15:BC15) -> 0 | BE15: =C15*BD15 -> 0
A16: 14 | BD16: =SUM(D16:BC16) -> 0 | BE16: =C16*BD16 -> 0
A17: 15 | BD17: =SUM(D17:BC17) -> 0 | BE17: =C17*BD17 -> 0
A18: 16 | BD18: =SUM(D18:BC18) -> 0 | BE18: =C18*BD18 -> 0
A19: 17 | BD19: =SUM(D19:BC19) -> 0 | BE19: =C19*BD19 -> 0
A20: 18 | BD20: =SUM(D20:BC20) -> 0 | BE20: =C20*BD20 -> 0
A21: 19 | BD21: =SUM(D21:BC21) -> 0 | BE21: =C21*BD21 -> 0
A22: 20 | BD22: =SUM(D22:BC22) -> 0 | BE22: =C22*BD22 -> 0
A23: Rework Type Count | BD23: =SUM(BD3:BD22) -> 2336000 | BE23: =SUM(BE3:BE22) -> 23743100
A24: 9 | B24: Rework Loss Type | C24: Product | D24: 1 | E24: =D24+1 -> 2 | F24: =E24+1 -> 3 | G24: =F24+1 -> 4 | H24: =G24+1 -> 5 | I24: =H24+1 -> 6 | J24: =I24+1 -> 7 | K24: =J24+1 -> 8 | L24: =K24+1 -> 9 | ... BC24: =BB24+1 -> 52 | BD24: Standard Rework Time (Seconds) | BE24: Standard Rework Baseline (%)
A25: 1 | B25: Rework Loss Type A | C25: =IF(OR(A$24>A25,A$24=A25),B$3,0) -> Product A | D25: 0 | E25: 0 | F25: 0 | G25: 0 | H25: 0 | I25: 0 | J25: 0 | K25: 0 | L25: 0 | M25: 0 | N25: 0 | O25: 0 | P25: 0 | Q25: 0 | R25: 0 | S25: 0 | T25: 0 | U25: 0 | V25: 0 | W25: 0 | X25: 0 | Y25: 0 | Z25: 0 | AA25: 0 | AB25: 0 | AC25: 0 | AD25: 0 | AE25: 0 | AF25: 0 | AG25: 0 | AH25: 0 | AI25: 0 | AJ25: 0 | AK25: 0 | AL25: 0 | AM25: 0 | AN25: 0 | AO25: 0 | AP25: 0 | AQ25: 0 | AR25: 0 | AS25: 0 | AT25: 0 | AU25: 0 | AV25: 0 | AW25: 0 | AX25: 0 | AY25: 0 | AZ25: 0 | BA25: 0 | BB25: 0 | BC25: 0 | BD25: 1 | BE25: 0.0005 | BG25: =SUM(D25:BC33) -> 319
A26: 2 | B26: Rework Loss Type B | C26: =IF(OR(A$24>A26,A$24=A26),B$3,0) -> Product A | D26: 19 | E26: 0 | F26: 11 | G26: 0 | H26: 19 | I26: 0 | J26: 0 | K26: 0 | L26: 19 | M26: 0 | N26: 0 | O26: 0 | P26: 19 | Q26: 8 | R26: 0 | S26: 0 | T26: 19 | U26: 0 | V26: 0 | W26: 6 | X26: 19 | Y26: 0 | Z26: 0 | AA26: 0 | AB26: 19 | AC26: 0 | AD26: 13 | AE26: 0 | AF26: 19 | AG26: 0 | AH26: 0 | AI26: 6 | AJ26: 20 | AK26: 0 | AL26: 0 | AM26: 0 | AN26: 19 | AO26: 6 | AP26: 0 | AQ26: 0 | AR26: 19 | AS26: 0 | AT26: 11 | AU26: 0 | AV26: 18 | AW26: 11 | AX26: 0 | AY26: 0 | AZ26: 19 | BA26: 0 | BB26: 0 | BC26: 0 | BD26: 2 | BE26: =BE25 -> 0.0005
A27: 3 | B27: Rework Loss Type C | C27: =IF(OR(A$24>A27,A$24=A27),B$3,0) -> Product A | D27: 0 | E27: 0 | F27: 0 | G27: 0 | H27: 0 | I27: 0 | J27: 0 | K27: 0 | L27: 0 | M27: 0 | N27: 0 | O27: 0 | P27: 0 | Q27: 0 | R27: 0 | S27: 0 | T27: 0 | U27: 0 | V27: 0 | W27: 0 | X27: 0 | Y27: 0 | Z27: 0 | AA27: 0 | AB27: 0 | AC27: 0 | AD27: 0 | AE27: 0 | AF27: 0 | AG27: 0 | AH27: 0 | AI27: 0 | AJ27: 0 | AK27: 0 | AL27: 0 | AM27: 0 | AN27: 0 | AO27: 0 | AP27: 0 | AQ27: 0 | AR27: 0 | AS27: 0 | AT27: 0 | AU27: 0 | AV27: 0 | AW27: 0 | AX27: 0 | AY27: 0 | AZ27: 0 | BA27: 0 | BB27: 0 | BC27: 0 | BD27: 4 | BE27: =BE26 -> 0.0005
A28: 4 | B28: Rework Loss Type D | C28: =IF(OR(A$24>A28,A$24=A28),B$3,0) -> Product A | D28: 0 | E28: 0 | F28: 0 | G28: 0 | H28: 0 | I28: 0 | J28: 0 | K28: 0 | L28: 0 | M28: 0 | N28: 0 | O28: 0 | P28: 0 | Q28: 0 | R28: 0 | S28: 0 | T28: 0 | U28: 0 | V28: 0 | W28: 0 | X28: 0 | Y28: 0 | Z28: 0 | AA28: 0 | AB28: 0 | AC28: 0 | AD28: 0 | AE28: 0 | AF28: 0 | AG28: 0 | AH28: 0 | AI28: 0 | AJ28: 0 | AK28: 0 | AL28: 0 | AM28: 0 | AN28: 0 | AO28: 0 | AP28: 0 | AQ28: 0 | AR28: 0 | AS28: 0 | AT28: 0 | AU28: 0 | AV28: 0 | AW28: 0 | AX28: 0 | AY28: 0 | AZ28: 0 | BA28: 0 | BB28: 0 | BC28: 0 | BD28: 2 | BE28: =BE27 -> 0.0005
A29: 5 | B29: Rework Loss Type E | C29: =IF(OR(A$24>A29,A$24=A29),B$3,0) -> Product A | D29: 0 | E29: 0 | F29: 0 | G29: 0 | H29: 0 | I29: 0 | J29: 0 | K29: 0 | L29: 0 | M29: 0 | N29: 0 | O29: 0 | P29: 0 | Q29: 0 | R29: 0 | S29: 0 | T29: 0 | U29: 0 | V29: 0 | W29: 0 | X29: 0 | Y29: 0 | Z29: 0 | AA29: 0 | AB29: 0 | AC29: 0 | AD29: 0 | AE29: 0 | AF29: 0 | AG29: 0 | AH29: 0 | AI29: 0 | AJ29: 0 | AK29: 0 | AL29: 0 | AM29: 0 | AN29: 0 | AO29: 0 | AP29: 0 | AQ29: 0 | AR29: 0 | AS29: 0 | AT29: 0 | AU29: 0 | AV29: 0 | AW29: 0 | AX29: 0 | AY29: 0 | AZ29: 0 | BA29: 0 | BB29: 0 | BC29: 0 | BD29: 2 | BE29: =BE28 -> 0.0005
A30: 6 | B30: Rework Loss Type F | C30: =IF(OR(A$24>A30,A$24=A30),B$3,0) -> Product A | D30: 0 | E30: 0 | F30: 0 | G30: 0 | H30: 0 | I30: 0 | J30: 0 | K30: 0 | L30: 0 | M30: 0 | N30: 0 | O30: 0 | P30: 0 | Q30: 0 | R30: 0 | S30: 0 | T30: 0 | U30: 0 | V30: 0 | W30: 0 | X30: 0 | Y30: 0 | Z30: 0 | AA30: 0 | AB30: 0 | AC30: 0 | AD30: 0 | AE30: 0 | AF30: 0 | AG30: 0 | AH30: 0 | AI30: 0 | AJ30: 0 | AK30: 0 | AL30: 0 | AM30: 0 | AN30: 0 | AO30: 0 | AP30: 0 | AQ30: 0 | AR30: 0 | AS30: 0 | AT30: 0 | AU30: 0 | AV30: 0 | AW30: 0 | AX30: 0 | AY30: 0 | AZ30: 0 | BA30: 0 | BB30: 0 | BC30: 0 | BD30: 4.5 | BE30: =BE29 -> 0.0005
A31: 7 | B31: Rework Loss Type G | C31: =IF(OR(A$24>A31,A$24=A31),B$3,0) -> Product A | D31: 0 | E31: 0 | F31: 0 | G31: 0 | H31: 0 | I31: 0 | J31: 0 | K31: 0 | L31: 0 | M31: 0 | N31: 0 | O31: 0 | P31: 0 | Q31: 0 | R31: 0 | S31: 0 | T31: 0 | U31: 0 | V31: 0 | W31: 0 | X31: 0 | Y31: 0 | Z31: 0 | AA31: 0 | AB31: 0 | AC31: 0 | AD31: 0 | AE31: 0 | AF31: 0 | AG31: 0 | AH31: 0 | AI31: 0 | AJ31: 0 | AK31: 0 | AL31: 0 | AM31: 0 | AN31: 0 | AO31: 0 | AP31: 0 | AQ31: 0 | AR31: 0 | AS31: 0 | AT31: 0 | AU31: 0 | AV31: 0 | AW31: 0 | AX31: 0 | AY31: 0 | AZ31: 0 | BA31: 0 | BB31: 0 | BC31: 0 | BD31: 1 | BE31: =BE30 -> 0.0005
A32: 8 | B32: Rework Loss Type H | C32: =IF(OR(A$24>A32,A$24=A32),B$3,0) -> Product A | D32: 0 | E32: 0 | F32: 0 | G32: 0 | H32: 0 | I32: 0 | J32: 0 | K32: 0 | L32: 0 | M32: 0 | N32: 0 | O32: 0 | P32: 0 | Q32: 0 | R32: 0 | S32: 0 | T32: 0 | U32: 0 | V32: 0 | W32: 0 | X32: 0 | Y32: 0 | Z32: 0 | AA32: 0 | AB32: 0 | AC32: 0 | AD32: 0 | AE32: 0 | AF32: 0 | AG32: 0 | AH32: 0 | AI32: 0 | AJ32: 0 | AK32: 0 | AL32: 0 | AM32: 0 | AN32: 0 | AO32: 0 | AP32: 0 | AQ32: 0 | AR32: 0 | AS32: 0 | AT32: 0 | AU32: 0 | AV32: 0 | AW32: 0 | AX32: 0 | AY32: 0 | AZ32: 0 | BA32: 0 | BB32: 0 | BC32: 0 | BD32: 2 | BE32: =BE31 -> 0.0005
A33: 9 | B33: Rework Loss Type I | C33: =IF(OR(A$24>A33,A$24=A33),B$3,0) -> Product A | D33: 0 | E33: 0 | F33: 0 | G33: 0 | H33: 0 | I33: 0 | J33: 0 | K33: 0 | L33: 0 | M33: 0 | N33: 0 | O33: 0 | P33: 0 | Q33: 0 | R33: 0 | S33: 0 | T33: 0 | U33: 0 | V33: 0 | W33: 0 | X33: 0 | Y33: 0 | Z33: 0 | AA33: 0 | AB33: 0 | AC33: 0 | AD33: 0 | AE33: 0 | AF33: 0 | AG33: 0 | AH33: 0 | AI33: 0 | AJ33: 0 | AK33: 0 | AL33: 0 | AM33: 0 | AN33: 0 | AO33: 0 | AP33: 0 | AQ33: 0 | AR33: 0 | AS33: 0 | AT33: 0 | AU33: 0 | AV33: 0 | AW33: 0 | AX33: 0 | AY33: 0 | AZ33: 0 | BA33: 0 | BB33: 0 | BC33: 0 | BD33: 2 | BE33: =BE32 -> 0.0005
A34: 10 | C34: =IF(OR(A$24>A34,A$24=A34),B$3,0) -> 0 | D34: 1 | E34: =D34+1 -> 2 | F34: =E34+1 -> 3 | G34: =F34+1 -> 4 | H34: =G34+1 -> 5 | I34: =H34+1 -> 6 | J34: =I34+1 -> 7 | K34: =J34+1 -> 8 | L34: =K34+1 -> 9 | ... BC34: =BB34+1 -> 52
A35: 1 | B35: =B25 -> Rework Loss Type A | C35: =IF(OR(A$24>A35,A$24=A35),B$4,0) -> Product B | D35: 0 | E35: 0 | F35: 0 | G35: 0 | H35: 0 | I35: 0 | J35: 0 | K35: 0 | L35: 0 | M35: 0 | N35: 0 | O35: 0 | P35: 0 | Q35: 0 | R35: 0 | S35: 0 | T35: 0 | U35: 0 | V35: 0 | W35: 0 | X35: 0 | Y35: 0 | Z35: 0 | AA35: 0 | AB35: 0 | AC35: 0 | AD35: 0 | AE35: 0 | AF35: 0 | AG35: 0 | AH35: 0 | AI35: 0 | AJ35: 0 | AK35: 0 | AL35: 0 | AM35: 0 | AN35: 0 | AO35: 0 | AP35: 0 | AQ35: 0 | AR35: 0 | AS35: 0 | AT35: 0 | AU35: 0 | AV35: 0 | AW35: 0 | AX35: 0 | AY35: 0 | AZ35: 0 | BA35: 0 | BB35: 0 | BC35: 0 | BD35: 1 | BE35: 0.0005 | BG35: =SUM(D35:BC43) -> 500
A36: 2 | B36: =B26 -> Rework Loss Type B | C36: =IF(OR(A$24>A36,A$24=A36),B$4,0) -> Product B | D36: 0 | E36: 0 | F36: 0 | G36: 0 | H36: 0 | I36: 0 | J36: 0 | K36: 0 | L36: 0 | M36: 0 | N36: 0 | O36: 0 | P36: 0 | Q36: 0 | R36: 0 | S36: 0 | T36: 0 | U36: 0 | V36: 0 | W36: 0 | X36: 0 | Y36: 0 | Z36: 0 | AA36: 0 | AB36: 0 | AC36: 0 | AD36: 0 | AE36: 0 | AF36: 0 | AG36: 0 | AH36: 0 | AI36: 0 | AJ36: 0 | AK36: 0 | AL36: 0 | AM36: 0 | AN36: 0 | AO36: 0 | AP36: 0 | AQ36: 0 | AR36: 0 | AS36: 0 | AT36: 0 | AU36: 0 | AV36: 0 | AW36: 0 | AX36: 0 | AY36: 0 | AZ36: 0 | BA36: 0 | BB36: 0 | BC36: 0 | BD36: 2 | BE36: =BE35 -> 0.0005
A37: 3 | B37: =B27 -> Rework Loss Type C | C37: =IF(OR(A$24>A37,A$24=A37),B$4,0) -> Product B | D37: 0 | E37: 0 | F37: 0 | G37: 0 | H37: 0 | I37: 0 | J37: 0 | K37: 0 | L37: 0 | M37: 0 | N37: 0 | O37: 0 | P37: 0 | Q37: 0 | R37: 0 | S37: 0 | T37: 0 | U37: 0 | V37: 0 | W37: 0 | X37: 0 | Y37: 0 | Z37: 0 | AA37: 0 | AB37: 0 | AC37: 0 | AD37: 0 | AE37: 0 | AF37: 0 | AG37: 0 | AH37: 0 | AI37: 0 | AJ37: 0 | AK37: 0 | AL37: 0 | AM37: 0 | AN37: 0 | AO37: 0 | AP37: 0 | AQ37: 0 | AR37: 0 | AS37: 0 | AT37: 0 | AU37: 0 | AV37: 0 | AW37: 0 | AX37: 0 | AY37: 0 | AZ37: 0 | BA37: 0 | BB37: 0 | BC37: 0 | BD37: 4 | BE37: =BE36 -> 0.0005
A38: 4 | B38: =B28 -> Rework Loss Type D | C38: =IF(OR(A$24>A38,A$24=A38),B$4,0) -> Product B | D38: 0 | E38: 0 | F38: 0 | G38: 0 | H38: 0 | I38: 0 | J38: 0 | K38: 0 | L38: 0 | M38: 0 | N38: 0 | O38: 0 | P38: 0 | Q38: 0 | R38: 0 | S38: 0 | T38: 0 | U38: 0 | V38: 0 | W38: 0 | X38: 0 | Y38: 0 | Z38: 0 | AA38: 0 | AB38: 0 | AC38: 0 | AD38: 0 | AE38: 0 | AF38: 0 | AG38: 0 | AH38: 0 | AI38: 0 | AJ38: 0 | AK38: 0 | AL38: 0 | AM38: 0 | AN38: 0 | AO38: 0 | AP38: 0 | AQ38: 0 | AR38: 0 | AS38: 0 | AT38: 0 | AU38: 0 | AV38: 0 | AW38: 0 | AX38: 0 | AY38: 0 | AZ38: 0 | BA38: 0 | BB38: 0 | BC38: 0 | BD38: 2 | BE38: =BE37 -> 0.0005
A39: 5 | B39: =B29 -> Rework Loss Type E | C39: =IF(OR(A$24>A39,A$24=A39),B$4,0) -> Product B | D39: 17 | E39: 19 | F39: 0 | G39: 13 | H39: 17 | I39: 19 | J39: 0 | K39: 7 | L39: 17 | M39: 19 | N39: 0 | O39: 0 | P39: 18 | Q39: 19 | R39: 0 | S39: 0 | T39: 17 | U39: 19 | V39: 0 | W39: 0 | X39: 17 | Y39: 19 | Z39: 0 | AA39: 0 | AB39: 17 | AC39: 19 | AD39: 0 | AE39: 0 | AF39: 17 | AG39: 19 | AH39: 0 | AI39: 0 | AJ39: 18 | AK39: 19 | AL39: 0 | AM39: 0 | AN39: 17 | AO39: 19 | AP39: 0 | AQ39: 0 | AR39: 17 | AS39: 19 | AT39: 0 | AU39: 10 | AV39: 18 | AW39: 20 | AX39: 0 | AY39: 9 | AZ39: 17 | BA39: 8 | BB39: 0 | BC39: 0 | BD39: 2 | BE39: =BE38 -> 0.0005
A40: 6 | B40: =B30 -> Rework Loss Type F | C40: =IF(OR(A$24>A40,A$24=A40),B$4,0) -> Product B | D40: 0 | E40: 0 | F40: 0 | G40: 0 | H40: 0 | I40: 0 | J40: 0 | K40: 0 | L40: 0 | M40: 0 | N40: 0 | O40: 0 | P40: 0 | Q40: 0 | R40: 0 | S40: 0 | T40: 0 | U40: 0 | V40: 0 | W40: 0 | X40: 0 | Y40: 0 | Z40: 0 | AA40: 0 | AB40: 0 | AC40: 0 | AD40: 0 | AE40: 0 | AF40: 0 | AG40: 0 | AH40: 0 | AI40: 0 | AJ40: 0 | AK40: 0 | AL40: 0 | AM40: 0 | AN40: 0 | AO40: 0 | AP40: 0 | AQ40: 0 | AR40: 0 | AS40: 0 | AT40: 0 | AU40: 0 | AV40: 0 | AW40: 0 | AX40: 0 | AY40: 0 | AZ40: 0 | BA40: 0 | BB40: 0 | BC40: 0 | BD40: 7 | BE40: =BE39 -> 0.0005
...

Sheet Micro Data Tabulation
B2: Operation Day / Per Week (day) | C2: ='Client Data'!F107 -> 7 | D2: Number of Hours / Shift (Hours) | H2: ='Client Data'!C107 -> 8 | I2: Unscheduled DT Baseline (Hours) | M2: ='Client Data'!J107 -> 0 | N2: Cycle Time Target Average (Seconds) | R2: =C6/AE3*60*60 -> 12.645 | S2: Customer Return Baseline | W2: ='Client Data'!Z106 -> 0 | AC2: Overhead Cost / Hr (RM) | AE2: ='Client Data'!AF106 -> 30
B3: Total Number of Validated Week | C3: ='Client Data'!AF107 -> 52 | D3: Number of Shift Per Day (Shift) | H3: ='Client Data'!F106 -> 3 | I3: Yield Loss Target Average (%) | M3: =SUM(M10:M29)/AE3 -> 0.00024645548 | N3: Number Of Customer Return Total | R3: =SUM(N10:N29) -> 12 | S3: Average Rework Cost / Unit (RM) | W3: =BC722/(SUM(BC537:BC544)-SUM(BC698:BC705)) -> 14.745328 | AC3: Total Volume (Output) | AE3: =SUM(O10:O17) -> 2336000
B4: Total Number of Validated Days | C4: =C2*C3 -> 364 | D4: Equipment Target Utilizatiion (%) | H4: ='Client Data'!C106 -> 0.9 | I4: Rework Loss Target Average (%) | M4: =SUM(L10:L29)/AE3 -> 0.00041862158 | N4: Manning Ratio | R4: ='Client Data'!S106 -> 2 | S4: Average DT cost / hour | W4: =BC180/BC162 -> 2573.6832 | X4: Labor Cost / Pax / Hour (RM) | AB4: ='Client Data'!AC107 -> 12 | AC4: Opportunity Cost / Hour | AE4: =BC311/SUM(BC295:BC302) -> 2519.2099
B5: Validated Period (Hours) | C5: =60*60*H2*H3*C4/(60*60) -> 8736 | D5: Total Production Planned Time (seconds) | H5: =C5-H6 -> 8372.3 | I5: Total Unscheduled Downtime (Hours) | M5: =BC94 -> 167.1 | N5: Average Yield Scrap Cost / Unit (RM) | R5: =C316 -> 16.051252
B6: Total Operation Time (hour) | C6: =H5-M5 -> 8205.2 | D6: Total Scheduled Downtime (Hours) | H6: =BC93 -> 363.7 | I6: Scheduled Downtime Baseline (Hours) | M6: ='Client Data'!S107 -> 0 | N6: Average DT Cost / Hour (Hour) | R6: =BC88/BC94 -> 2573.6832
B9: ='Client Data'!B2 -> Product Name | C9: ='Client Data'!C2 -> Standard CT (Seconds) | D9: ='Client Data'!BD24 -> Standard Rework Time (Seconds) | E9: ='Client Data'!BF2 -> Rework Extra Material Cost / Unit (RM) | F9: ='Client Data'!BG2 -> Rework: Extra Utility Cost (RM) | G9: ='Client Data'!BH2 -> Product Price / Unit (RM) | H9: ='Client Data'!BI2 -> Material Cost / Unit (RM) | I9: ='Client Data'!BJ2 -> Utility Cost / Unit (RM) | J9: ='Client Data'!BK2 -> Yeild Target (%) | K9: Allowable Yield Loss Baseline (%) | L9: Rework Target / Baseline Quantity | M9: Yield Loss Target / Baseline Quantity | N9: ='Client Data'!BL2 -> Customer Return | O9: Output Quantity | P9: Standard Total Operation Time (Seconds) | Q9: Allowable Rework Baseline (%)
B10: ='Client Data'!B3 -> Product A | C10: ='Client Data'!C3 -> 9 | D10: =SUM('Client Data'!BD25:BD33) -> 20.5 | E10: ='Client Data'!BF3 -> 0.24 | F10: ='Client Data'!BG3 -> 0.26 | G10: ='Client Data'!BH3 -> 26 | H10: ='Client Data'!BI3 -> 7 | I10: ='Client Data'!BJ3 -> 8.5 | J10: ='Client Data'!BK3 -> 0.9997 | K10: =1-J10 -> 0.0003 | L10: =Q10*O10 -> 75 | M10: =K10*O10 -> 45 | N10: ='Client Data'!BL3 -> 1 | O10: =SUM(C763:BB763) -> 150000 | P10: =C10*O10 -> 1350000 | Q10: ='Client Data'!BE25 -> 0.0005
B11: ='Client Data'!B4 -> Product B | C11: ='Client Data'!C4 -> 9.8 | D11: =SUM('Client Data'!BD35:BD43) -> 23 | E11: ='Client Data'!BF4 -> 0.23 | F11: ='Client Data'!BG4 -> 0.23 | G11: ='Client Data'!BH4 -> 25 | H11: ='Client Data'!BI4 -> 8 | I11: ='Client Data'!BJ4 -> 8.9 | J11: ='Client Data'!BK4 -> 0.99971 | K11: =1-J11 -> 0.00029 | L11: =Q11*O11 -> 116 | M11: =K11*O11 -> 67.28 | N11: ='Client Data'!BL4 -> 2 | O11: =SUM(C764:BB764) -> 232000 | P11: =C11*O11 -> 2273600 | Q11: ='Client Data'!BE35 -> 0.0005
B12: ='Client Data'!B5 -> Product C | C12: ='Client Data'!C5 -> 9.6 | D12: =SUM('Client Data'!BD45:BD53) -> 20 | E12: ='Client Data'!BF5 -> 0.22 | F12: ='Client Data'!BG5 -> 0.25 | G12: ='Client Data'!BH5 -> 24 | H12: ='Client Data'!BI5 -> 6 | I12: ='Client Data'!BJ5 -> 9 | J12: ='Client Data'!BK5 -> 0.99975 | K12: =1-J12 -> 0.00025 | L12: =Q12*O12 -> 105.3 | M12: =K12*O12 -> 87.75 | N12: ='Client Data'!BL5 -> 2 | O12: =SUM(C765:BB765) -> 351000 | P12: =C12*O12 -> 3369600 | Q12: ='Client Data'!BE45 -> 0.0003
B13: ='Client Data'!B6 -> Product D | C13: ='Client Data'!C6 -> 11 | D13: =SUM('Client Data'!BD55:BD63) -> 18.8 | E13: ='Client Data'!BF6 -> 0.21 | F13: ='Client Data'!BG6 -> 0.22 | G13: ='Client Data'!BH6 -> 21 | H13: ='Client Data'!BI6 -> 8.5 | I13: ='Client Data'!BJ6 -> 8 | J13: ='Client Data'!BK6 -> 0.99979 | K13: =1-J13 -> 0.00021 | L13: =Q13*O13 -> 248 | M13: =K13*O13 -> 104.16 | N13: ='Client Data'!BL6 -> 1 | O13: =SUM(C766:BB766) -> 496000 | P13: =C13*O13 -> 5456000 | Q13: ='Client Data'!BE55 -> 0.0005
B14: ='Client Data'!B7 -> Product E | C14: ='Client Data'!C7 -> 10.8 | D14: =SUM('Client Data'!BD65:BD73) -> 19.3 | E14: ='Client Data'!BF7 -> 0.23 | F14: ='Client Data'!BG7 -> 0.24 | G14: ='Client Data'!BH7 -> 23 | H14: ='Client Data'!BI7 -> 8 | I14: ='Client Data'!BJ7 -> 7.8 | J14: ='Client Data'!BK7 -> 0.99976 | K14: =1-J14 -> 0.00024 | L14: =Q14*O14 -> 176 | M14: =K14*O14 -> 105.6 | N14: ='Client Data'!BL7 -> 2 | O14: =SUM(C767:BB767) -> 440000 | P14: =C14*O14 -> 4752000 | Q14: ='Client Data'!BE65 -> 0.0004
B15: ='Client Data'!B8 -> Product F | C15: ='Client Data'!C8 -> 10.5 | D15: =SUM('Client Data'!BD75:BD83) -> 19.8 | E15: ='Client Data'!BF8 -> 0.24 | F15: ='Client Data'!BG8 -> 0.25 | G15: ='Client Data'!BH8 -> 22 | H15: ='Client Data'!BI8 -> 9 | I15: ='Client Data'!BJ8 -> 7.9 | J15: ='Client Data'!BK8 -> 0.99973 | K15: =1-J15 -> 0.00027 | L15: =Q15*O15 -> 138.8 | M15: =K15*O15 -> 93.69 | N15: ='Client Data'!BL8 -> 1 | O15: =SUM(C768:BB768) -> 347000 | P15: =C15*O15 -> 3643500 | Q15: ='Client Data'!BE75 -> 0.0004
B16: ='Client Data'!B9 -> Product G | C16: ='Client Data'!C9 -> 9 | D16: =SUM('Client Data'!BD85:BD93) -> 18.4 | E16: ='Client Data'!BF9 -> 0.22 | F16: ='Client Data'!BG9 -> 0.25 | G16: ='Client Data'!BH9 -> 24 | H16: ='Client Data'!BI9 -> 6.9 | I16: ='Client Data'!BJ9 -> 8 | J16: ='Client Data'!BK9 -> 0.99978 | K16: =1-J16 -> 0.00022 | L16: =Q16*O16 -> 91.2 | M16: =K16*O16 -> 50.16 | N16: ='Client Data'!BL9 -> 2 | O16: =SUM(C769:BB769) -> 228000 | P16: =C16*O16 -> 2052000 | Q16: ='Client Data'!BE85 -> 0.0004
B17: ='Client Data'!B10 -> Product H | C17: ='Client Data'!C10 -> 9.2 | D17: =SUM('Client Data'!BD95:BD103) -> 15.7 | E17: ='Client Data'!BF10 -> 0.25 | F17: ='Client Data'!BG10 -> 0.22 | G17: ='Client Data'!BH10 -> 26 | H17: ='Client Data'!BI10 -> 7.8 | I17: ='Client Data'!BJ10 -> 7.5 | J17: ='Client Data'!BK10 -> 0.99976 | K17: =1-J17 -> 0.00024 | L17: =Q17*O17 -> 27.6 | M17: =K17*O17 -> 22.08 | N17: ='Client Data'!BL10 -> 1 | O17: =SUM(C770:BB770) -> 92000 | P17: =C17*O17 -> 846400 | Q17: ='Client Data'!BE95 -> 0.0003
B18: ='Client Data'!B11 -> 0 | C18: ='Client Data'!C11 -> 0 | J18: 0 | K18: =1-J18 -> 1
B19: ='Client Data'!B12 -> 0 | C19: ='Client Data'!C12 -> 0 | J19: 0 | K19: =1-J19 -> 1
B20: ='Client Data'!B13 -> 0 | C20: ='Client Data'!C13 -> 0 | J20: 0 | K20: =1-J20 -> 1
B21: ='Client Data'!B14 -> 0 | C21: ='Client Data'!C14 -> 0 | J21: 0 | K21: =1-J21 -> 1
B22: ='Client Data'!B15 -> 0 | C22: ='Client Data'!C15 -> 0 | J22: 0 | K22: =1-J22 -> 1
B23: ='Client Data'!B16 -> 0 | C23: ='Client Data'!C16 -> 0 | J23: 0 | K23: =1-J23 -> 1
B24: ='Client Data'!B17 -> 0 | C24: ='Client Data'!C17 -> 0 | J24: 0 | K24: =1-J24 -> 1
B25: ='Client Data'!B18 -> 0 | C25: ='Client Data'!C18 -> 0 | J25: 0 | K25: =1-J25 -> 1
B26: ='Client Data'!B19 -> 0 | C26: ='Client Data'!C19 -> 0 | J26: 0 | K26: =1-J26 -> 1
B27: ='Client Data'!B20 -> 0 | C27: ='Client Data'!C20 -> 0 | J27: 0 | K27: =1-J27 -> 1
B28: ='Client Data'!B21 -> 0 | C28: ='Client Data'!C21 -> 0 | J28: 0 | K28: =1-J28 -> 1
B29: ='Client Data'!B22 -> 0 | C29: ='Client Data'!C22 -> 0 | J29: 0 | K29: =1-J29 -> 1
B32: Average KPI Summary
B33: Category | C33: Metric Description | G33: Unit | H33: Standard Value | K33: Actual Value | N33: Gap | Q33: Logic | R33: Gap Value | U33: Cost / Unit (RM) | X33: VAS (Validated Size) | AA33: 5-Years VAS | AD33: Logical Test
B34: Unscheduled Downtime | C34: Machine Failure | G34: Hr | H34: =M2 -> 0 | K34: =M5 -> 167.1 | N34: =H34-K34 -> -167.1 | Q34: =IF(N34<0,1,0) -> 1 | R34: =IF(Q34>0,N34*(-1),0) -> 167.1 | U34: =R6 -> 2573.6832 | X34: =R34*U34 -> 430062.47 | AA34: =C$3/52*5*X34 -> 2150312.3 | AD34: =IF(X34=BC88,TRUE,FALSE) -> TRUE
B35: Scheduled Downtime | C35: Planned Tool / Process Activities | G35: Hr | H35: =M6 -> 0 | K35: =H6 -> 363.7 | N35: =H35-K35 -> -363.7 | Q35: =IF(N35<0,1,0) -> 1 | R35: =IF(Q35>0,N35*(-1),0) -> 363.7 | U35: =BC265/SUM(BC249:BC256) -> 2575.5784 | X35: =R35*U35 -> 936737.85 | AA35: =C$3/52*5*X35 -> 4683689.3 | AD35: =IF(X35=BC91,TRUE,FALSE) -> TRUE
B36: Quality Loss (Yield Loss) | C36: Product Reject Rate | G36: % | H36: =M3 -> 0.00024645548 | K36: =BC68/AE3 -> 0.00045034247 | N36: =H36-K36 -> -0.00020388699 | Q36: =IF(N36<0,1,0) -> 1 | R36: =IF(Q36>0,N36*(-1)*AE3,0) -> 476.28 | U36: =R5 -> 16.051252 | X36: =R36*U36 -> 7644.8905 | AA36: =C$3/52*5*X36 -> 38224.453 | AD36: =IF(X36=BC453,TRUE,FALSE) -> TRUE
B37: Quality Loss (Rework Loss) | C37: Product Rework Rate | G37: % | H37: =M4 -> 0.00041862158 | K37: =BC75/AE3 -> 0.0021592466 | N37: =H37-K37 -> -0.001740625 | Q37: =IF(N37<0,1,0) -> 1 | R37: =IF(Q37>0,N37*(-1)*AE3,0) -> 4066.1 | U37: =W3 -> 14.745328 | X37: =R37*U37 -> 59955.976 | AA37: =C$3/52*5*X37 -> 299779.88 | AD37: =IF(X37=BC722,TRUE,FALSE) -> TRUE
B38: Speed Loss (ACT-TCT) | C38: Actual / Standard Operation Time | G38: Sec | H38: =SUM(P10:P29)/AE3 -> 10.163998 | K38: =C6*60*60/AE3 -> 12.645 | N38: =H38-K38 -> -2.4810017 | Q38: =IF(N38<0,1,0) -> 1 | R38: =IF(Q38>0,N38*(-1)*AE3/(60*60),0) -> 1609.8944 | U38: =AE4 -> 2519.2099 | X38: =R38*U38 -> 4055662 | AA38: =C$3/52*5*X38 -> 20278310 | AD38: =IF(X38=BC311,TRUE,FALSE) -> TRUE
B39: Labor Loss | C39: Actual / Standard Labor Hours | G39: Hr | H39: =SUM(P10:P29)/60/60*R4 -> 13190.611 | K39: =C2*H2*H3*C3*R4 -> 17472 | N39: =H39-K39 -> -4281.3889 | Q39: =IF(N39<0,1,0) -> 1 | R39: =IF(Q39>0,N39*(-1),0) -> 4281.3889 | U39: =AB4 -> 12 | X39: =R39*U39 -> 51376.667 | AA39: =C$3/52*5*X39 -> 256883.33 | AD39: =IF(X39=SUM(C759:BB759),TRUE,FALSE) -> TRUE
B40: Utility Waste | C40: Actual / Standard Utility Consumption | G40: RM | N40: =H40-K40 -> 0 | Q40: =IF(N40<0,1,0) -> 0 | R40: =IF(Q40>0,N40*(-1),0) -> 0
B41: Customer Return (unit) | C41: Product Failure Escapee | G41: unit | H41: =W2 -> 0 | K41: =R3 -> 12 | N41: =H41-K41 -> -12 | Q41: =IF(N41<0,1,0) -> 1 | R41: =IF(Q41>0,N41*(-1),0) -> 12 | U41: =R5 -> 16.051252 | X41: =R41*U41 -> 192.61503 | AA41: =C$3/52*5*X41 -> 963.07515 | AD41: TRUE
B42: Material Waste | C42: Actual / Standard Material Consumption | G42: RM | N42: =H42-K42 -> 0 | Q42: =IF(N42<0,1,0) -> 0 | R42: =IF(Q42>0,N42*(-1),0) -> 0
B43: Tooling / Consumables Waste | C43: Actual / Standard Others Consumption | G43: RM | N43: =H43-K43 -> 0 | Q43: =IF(N43<0,1,0) -> 0 | R43: =IF(Q43>0,N43*(-1),0) -> 0
G55: sec
B56: Week | C56: 1 | D56: =C56+1 -> 2 | E56: =D56+1 -> 3 | F56: =E56+1 -> 4 | G56: =F56+1 -> 5 | H56: =G56+1 -> 6 | I56: =H56+1 -> 7 | J56: =I56+1 -> 8 | K56: =J56+1 -> 9 | ... BB56: =BA56+1 -> 52 | BC56: TOTAL
...

Sheet Chart
B2: ='Val Size'!B28 -> Category | C2: ='Val Size'!E28 -> Val Size VaS
B3: ='Val Size'!B29 -> USDT - Machine Failure | C3: ='Val Size'!E29 -> 430062.47
B4: ='Val Size'!B30 -> USDT - Machine Assist | C4: ='Val Size'!E30 -> 0
B5: ='Val Size'!B31 -> Quality Loss - Defect | C5: ='Val Size'!E31 -> 7644.8905
B6: ='Val Size'!B32 -> Quality Loss - Rework | C6: ='Val Size'!E32 -> 59955.976
B7: ='Val Size'!B33 -> Speed Loss | C7: ='Val Size'!E33 -> 4352710.5
B8: ='Val Size'!B34 -> Labor Loss | C8: ='Val Size'!E34 -> 51376.667
B9: ='Val Size'!B35 -> Utility Waste | C9: ='Val Size'!E35 -> 19272
B10: ='Val Size'!B36 -> Customer Return | C10: ='Val Size'!E36 -> 193.07704
B11: ='Val Size'!B37 -> Material Waste | C11: ='Val Size'!E37 -> 36736
B12: ='Val Size'!B38 -> Tooling / Consulables Waste | C12: ='Val Size'!E38 -> 23496
B25: ='Micro Data Tabulation'!B56 -> Week | C25: ='Micro Data Tabulation'!C56 -> 1 | D25: ='Micro Data Tabulation'!D56 -> 2 | E25: ='Micro Data Tabulation'!E56 -> 3 | F25: ='Micro Data Tabulation'!F56 -> 4 | G25: ='Micro Data Tabulation'!G56 -> 5 | H25: ='Micro Data Tabulation'!H56 -> 6 | I25: ='Micro Data Tabulation'!I56 -> 7 | ... BB25: ='Micro Data Tabulation'!BB56 -> 52
B26: ='Micro Data Tabulation'!B57 -> Production (Volume) - Weekly (Unit) | C26: ='Micro Data Tabulation'!C57 -> 45000 | D26: ='Micro Data Tabulation'!D57 -> 48000 | E26: ='Micro Data Tabulation'!E57 -> 51000 | F26: ='Micro Data Tabulation'!F57 -> 39000 | G26: ='Micro Data Tabulation'!G57 -> 41000 | H26: ='Micro Data Tabulation'!H57 -> 43000 | I26: ='Micro Data Tabulation'!I57 -> 45000 | ... BB26: ='Micro Data Tabulation'!BB57 -> 43000
B27: ='Micro Data Tabulation'!B64 -> Yield / Quality (%) - Weekly | C27: ='Micro Data Tabulation'!C64*100 -> 99.953333 | D27: ='Micro Data Tabulation'!D64*100 -> 99.958333 | E27: ='Micro Data Tabulation'!E64*100 -> 99.952941 | F27: ='Micro Data Tabulation'!F64*100 -> 99.953846 | G27: ='Micro Data Tabulation'!G64*100 -> 99.953659 | H27: ='Micro Data Tabulation'!H64*100 -> 99.953488 | I27: ='Micro Data Tabulation'!I64*100 -> 99.957778 | J27: ='Micro Data Tabulation'!J64*100 -> 99.954167 | ... BB27: ='Micro Data Tabulation'!BB64*100 -> 99.960465
